Workbook

Sheet Price Data
A3: Date | B3: VTI | C3: EFA | D3: VNQ | E3: AGG
A4: 2021-01-06 | B4: 180.7865 | C4: 63.165077 | D4: 67.145844 | E4: 99.167175
A5: 2021-01-07 | B5: 183.686 | C5: 63.23251 | D5: 67.015503 | E5: 99.065765
A6: 2021-01-08 | B6: 184.57529 | C6: 63.822445 | D6: 67.66716 | E6: 98.947433
A7: 2021-01-11 | B7: 183.47293 | C7: 62.988091 | D7: 66.771126 | E7: 98.786858
A8: 2021-01-12 | B8: 184.12137 | C8: 63.274639 | D8: 66.925896 | E8: 98.871391
A9: 2021-01-13 | B9: 184.3252 | C9: 63.190372 | D9: 67.740479 | E9: 99.184082
A10: 2021-01-14 | B10: 184.14917 | C10: 63.696033 | D10: 68.13961 | E10: 98.989685
A11: 2021-01-15 | B11: 182.54662 | C11: 62.701565 | D11: 68.921608 | E11: 99.091118
A12: 2021-01-19 | B12: 184.21404 | C12: 63.156662 | D12: 68.726128 | E12: 99.226357
A13: 2021-01-20 | B13: 186.53917 | C13: 63.586456 | D13: 70.03759 | E13: 99.23481
A14: 2021-01-21 | B14: 186.40016 | C14: 63.637032 | D14: 69.703606 | E14: 99.091118
A15: 2021-01-22 | B15: 186.09456 | C15: 63.333633 | D15: 69.866531 | E15: 99.091118
... A1379: 2026-06-30 | B1379: 370.04001 | C1379: 103.88 | D1379: 96.43 | E1379: 98.649002

Sheet Returns  Stats
A3: Date | B3: VTI | C3: EFA | D3: VNQ | E3: AGG
A4: 2021-01-07 | B4: ='Price Data'!B5/'Price Data'!B4-1 -> 0.016038286 | C4: ='Price Data'!C5/'Price Data'!C4-1 -> 0.0010675583 | D4: ='Price Data'!D5/'Price Data'!D4-1 -> -0.0019411563 | E4: ='Price Data'!E5/'Price Data'!E4-1 -> -0.0010226157
A5: 2021-01-08 | B5: ='Price Data'!B6/'Price Data'!B5-1 -> 0.0048413173 | C5: ='Price Data'!C6/'Price Data'!C5-1 -> 0.0093296203 | D5: ='Price Data'!D6/'Price Data'!D5-1 -> 0.0097239754 | E5: ='Price Data'!E6/'Price Data'!E5-1 -> -0.0011944783
A6: 2021-01-11 | B6: ='Price Data'!B7/'Price Data'!B6-1 -> -0.0059723919 | C6: ='Price Data'!C7/'Price Data'!C6-1 -> -0.013073056 | D6: ='Price Data'!D7/'Price Data'!D6-1 -> -0.013241789 | E6: ='Price Data'!E7/'Price Data'!E6-1 -> -0.0016228401
A7: 2021-01-12 | B7: ='Price Data'!B8/'Price Data'!B7-1 -> 0.0035342407 | C7: ='Price Data'!C8/'Price Data'!C7-1 -> 0.0045492507 | D7: ='Price Data'!D8/'Price Data'!D7-1 -> 0.0023179165 | E7: ='Price Data'!E8/'Price Data'!E7-1 -> 0.00085571799
A8: 2021-01-13 | B8: ='Price Data'!B9/'Price Data'!B8-1 -> 0.0011070247 | C8: ='Price Data'!C9/'Price Data'!C8-1 -> -0.0013317605 | D8: ='Price Data'!D9/'Price Data'!D8-1 -> 0.012171415 | E8: ='Price Data'!E9/'Price Data'!E8-1 -> 0.0031626007
A9: 2021-01-14 | B9: ='Price Data'!B10/'Price Data'!B9-1 -> -0.00095497195 | C9: ='Price Data'!C10/'Price Data'!C9-1 -> 0.0080021844 | D9: ='Price Data'!D10/'Price Data'!D9-1 -> 0.005892072 | E9: ='Price Data'!E10/'Price Data'!E9-1 -> -0.0019599614
A10: 2021-01-15 | B10: ='Price Data'!B11/'Price Data'!B10-1 -> -0.0087024792 | C10: ='Price Data'!C11/'Price Data'!C10-1 -> -0.015612726 | D10: ='Price Data'!D11/'Price Data'!D10-1 -> 0.011476404 | E10: ='Price Data'!E11/'Price Data'!E10-1 -> 0.0010246805
A11: 2021-01-19 | B11: ='Price Data'!B12/'Price Data'!B11-1 -> 0.0091342117 | C11: ='Price Data'!C12/'Price Data'!C11-1 -> 0.0072581474 | D11: ='Price Data'!D12/'Price Data'!D11-1 -> -0.0028362708 | E11: ='Price Data'!E12/'Price Data'!E11-1 -> 0.0013647908
A12: 2021-01-20 | B12: ='Price Data'!B13/'Price Data'!B12-1 -> 0.012621917 | C12: ='Price Data'!C13/'Price Data'!C12-1 -> 0.0068052094 | D12: ='Price Data'!D13/'Price Data'!D12-1 -> 0.019082443 | E12: ='Price Data'!E13/'Price Data'!E12-1 -> 8.519278e-05
A13: 2021-01-21 | B13: ='Price Data'!B14/'Price Data'!B13-1 -> -0.00074519238 | C13: ='Price Data'!C14/'Price Data'!C13-1 -> 0.00079537781 | D13: ='Price Data'!D14/'Price Data'!D13-1 -> -0.0047686446 | E13: ='Price Data'!E14/'Price Data'!E13-1 -> -0.0014480001
A14: 2021-01-22 | B14: ='Price Data'!B15/'Price Data'!B14-1 -> -0.0016394998 | C14: ='Price Data'!C15/'Price Data'!C14-1 -> -0.0047676349 | D14: ='Price Data'!D15/'Price Data'!D14-1 -> 0.0023374074 | E14: ='Price Data'!E15/'Price Data'!E14-1 -> 0
A15: 2021-01-25 | B15: ='Price Data'!B16/'Price Data'!B15-1 -> 0.0028371026 | C15: ='Price Data'!C16/'Price Data'!C15-1 -> -0.001197468 | D15: ='Price Data'!D16/'Price Data'!D15-1 -> 0.0075783403 | E15: ='Price Data'!E16/'Price Data'!E15-1 -> 0.0025588865
... A1378: 2026-06-30 | B1378: ='Price Data'!B1379/'Price Data'!B1378-1 -> 0.0079538393 | C1378: ='Price Data'!C1379/'Price Data'!C1378-1 -> 0.0041566005 | D1378: ='Price Data'!D1379/'Price Data'!D1378-1 -> -0.01752421 | E1378: ='Price Data'!E1379/'Price Data'!E1378-1 -> -0.0039247153
A1381: Summary Statistics
B1382: VTI | C1382: EFA | D1382: VNQ | E1382: AGG
A1383: Mean Daily Return | B1383: =AVERAGE(B4:B1378) -> 0.00057995469 | C1383: =AVERAGE(C4:C1378) -> 0.00041459551 | D1383: =AVERAGE(D4:D1378) -> 0.0003314393 | E1383: =AVERAGE(E4:E1378) -> 3.1384519e-06
A1384: Daily Std Dev | B1384: =STDEV(B4:B1378) -> 0.010863086 | C1384: =STDEV(C4:C1378) -> 0.010279416 | D1384: =STDEV(D4:D1378) -> 0.0116809 | E1384: =STDEV(E4:E1378) -> 0.0037295081
A1385: Daily Variance | B1385: =VAR(B4:B1378) -> 0.00011800664 | C1385: =VAR(C4:C1378) -> 0.0001056664 | D1385: =VAR(D4:D1378) -> 0.00013644341 | E1385: =VAR(E4:E1378) -> 1.3909231e-05
A1386: Annualised Return (×252) | B1386: =B1383*252 -> 0.14614858 | C1386: =C1383*252 -> 0.10447807 | D1386: =D1383*252 -> 0.083522703 | E1386: =E1383*252 -> 0.00079088988
A1387: Annualised Std Dev (×√252) | B1387: =B1384*SQRT(252) -> 0.17244615 | C1387: =C1384*SQRT(252) -> 0.16318068 | D1387: =D1384*SQRT(252) -> 0.18542853 | E1387: =E1384*SQRT(252) -> 0.059204106
A1390: Correlation Matrix
B1391: VTI | C1391: EFA | D1391: VNQ | E1391: AGG
A1392: VTI | B1392: =CORREL(B4:B1378,B4:B1378) -> 1 | C1392: =CORREL(B4:B1378,C4:C1378) -> 0.80983747 | D1392: =CORREL(B4:B1378,D4:D1378) -> 0.68102311 | E1392: =CORREL(B4:B1378,E4:E1378) -> 0.21729339
A1393: EFA | B1393: =CORREL(C4:C1378,B4:B1378) -> 0.80983747 | C1393: =CORREL(C4:C1378,C4:C1378) -> 1 | D1393: =CORREL(C4:C1378,D4:D1378) -> 0.62585975 | E1393: =CORREL(C4:C1378,E4:E1378) -> 0.27490852
A1394: VNQ | B1394: =CORREL(D4:D1378,B4:B1378) -> 0.68102311 | C1394: =CORREL(D4:D1378,C4:C1378) -> 0.62585975 | D1394: =CORREL(D4:D1378,D4:D1378) -> 1 | E1394: =CORREL(D4:D1378,E4:E1378) -> 0.38474912
A1395: AGG | B1395: =CORREL(E4:E1378,B4:B1378) -> 0.21729339 | C1395: =CORREL(E4:E1378,C4:C1378) -> 0.27490852 | D1395: =CORREL(E4:E1378,D4:D1378) -> 0.38474912 | E1395: =CORREL(E4:E1378,E4:E1378) -> 1
A1398: Variance-Covariance Matrix (Annualised)
B1399: VTI | C1399: EFA | D1399: VNQ | E1399: AGG
A1400: VTI | B1400: =SUMPRODUCT((B4:B1378-B$1383),(B4:B1378-B$1383))/1375*252 -> 0.029716046 | C1400: =SUMPRODUCT((B4:B1378-B$1383),(C4:C1378-C$1383))/1375*252 -> 0.022772155 | D1400: =SUMPRODUCT((B4:B1378-B$1383),(D4:D1378-D$1383))/1375*252 -> 0.021760854 | E1400: =SUMPRODUCT((B4:B1378-B$1383),(E4:E1378-E$1383))/1375*252 -> 0.0022168477
A1401: EFA | B1401: =SUMPRODUCT((C4:C1378-C$1383),(B4:B1378-B$1383))/1375*252 -> 0.022772155 | C1401: =SUMPRODUCT((C4:C1378-C$1383),(C4:C1378-C$1383))/1375*252 -> 0.026608567 | D1401: =SUMPRODUCT((C4:C1378-C$1383),(D4:D1378-D$1383))/1375*252 -> 0.018923712 | E1401: =SUMPRODUCT((C4:C1378-C$1383),(E4:E1378-E$1383))/1375*252 -> 0.0026539503
A1402: VNQ | B1402: =SUMPRODUCT((D4:D1378-D$1383),(B4:B1378-B$1383))/1375*252 -> 0.021760854 | C1402: =SUMPRODUCT((D4:D1378-D$1383),(C4:C1378-C$1383))/1375*252 -> 0.018923712 | D1402: =SUMPRODUCT((D4:D1378-D$1383),(D4:D1378-D$1383))/1375*252 -> 0.034358734 | E1402: =SUMPRODUCT((D4:D1378-D$1383),(E4:E1378-E$1383))/1375*252 -> 0.0042207542
A1403: AGG | B1403: =SUMPRODUCT((E4:E1378-E$1383),(B4:B1378-B$1383))/1375*252 -> 0.0022168477 | C1403: =SUMPRODUCT((E4:E1378-E$1383),(C4:C1378-C$1383))/1375*252 -> 0.0026539503 | D1403: =SUMPRODUCT((E4:E1378-E$1383),(D4:D1378-D$1383))/1375*252 -> 0.0042207542 | E1403: =SUMPRODUCT((E4:E1378-E$1383),(E4:E1378-E$1383))/1375*252 -> 0.003502577

Sheet MPT Optimisation
A3: Portfolio value (USD) | B3: 20000000
A4: Risk-free rate (Fed funds upper bound, proxy) | B4: 0.0375
A6: Asset-Level Annualised Statistics
A7: Asset | B7: Annualised Return | C7: Annualised Std Dev
A8: VTI | B8: ='Returns Stats'!B1386 -> 0.14614858 | C8: ='Returns Stats'!B1387 -> 0.17244615
A9: EFA | B9: ='Returns Stats'!C1386 -> 0.10447807 | C9: ='Returns Stats'!C1387 -> 0.16318068
A10: VNQ | B10: ='Returns Stats'!D1386 -> 0.083522703 | C10: ='Returns Stats'!D1387 -> 0.18542853
A11: AGG | B11: ='Returns Stats'!E1386 -> 0.00079088988 | C11: ='Returns Stats'!E1387 -> 0.059204106
A14: Optimal Portfolio — Maximum Sharpe Ratio (Solver-derived weights)
A15: Asset | B15: Weight | C15: Weighted Return Contribution
A16: VTI | B16: 0.6 | C16: =B16*B8 -> 0.087689149
A17: EFA | B17: 0.3 | C17: =B17*B9 -> 0.03134342
A18: VNQ | B18: 0.05 | C18: =B18*B10 -> 0.0041761352
A19: AGG | B19: 0.05 | C19: =B19*B11 -> 3.9544494e-05
A20: Total | B20: =SUM(B16:B19) -> 1
A22: Portfolio Expected Return | B22: =SUM(C16:C19) -> 0.12324825
A23: Portfolio Variance (Annualised) | B23: =B16*B16*'Returns Stats'!B1400+B16*B17*'Returns Stats'!C1400+B16*B18*'Returns Stats'!D1400+B16*B19*'Returns Stats'!E1400+B17*B16*'Returns Stats'!B1401+B17*B17*'Returns Stats'!C1401+B17*B18*'Returns Stats'!D1401+B17*B19*'Returns Stats'!E1401+B18*B16*'Returns Stats'!B1402+B18*B17*'Returns Stats'!C1402+B18*B18*'Returns Stats'!D1402+B18*B19*'Returns Stats'!E1402+B19*B16*'Returns Stats'!B1403+B19*B17*'Returns Stats'!C1403+B19*B18*'Returns Stats'!D1403+B19*B19*'Returns Stats'!E1403 -> 0.023492272
A24: Portfolio Std Dev (Volatility) | B24: =SQRT(B23) -> 0.15327189
A25: Sharpe Ratio | B25: =(B22-B4)/B24 -> 0.55945189
A27: USD Allocation (of $20m)
A28: VTI | B28: =B16*$B$3 -> 12000000
A29: EFA | B29: =B17*$B$3 -> 6000000
A30: VNQ | B30: =B18*$B$3 -> 1000000
A31: AGG | B31: =B19*$B$3 -> 1000000
A34: Comparator — Minimum Variance Portfolio
A35: Asset | B35: Weight
A36: VTI | B36: 0.14106604
A37: EFA | B37: 0.20651842
A38: VNQ | B38: 0.052415548
A39: AGG | B39: 0.6
A40: Portfolio Return | B40: =B36*B8+B37*B9+B38*B10+B39*B11 -> 0.047045668
A41: Portfolio Variance | B41: =B36*B36*'Returns Stats'!B1400+B36*B37*'Returns Stats'!C1400+B36*B38*'Returns Stats'!D1400+B36*B39*'Returns Stats'!E1400+B37*B36*'Returns Stats'!B1401+B37*B37*'Returns Stats'!C1401+B37*B38*'Returns Stats'!D1401+B37*B39*'Returns Stats'!E1401+B38*B36*'Returns Stats'!B1402+B38*B37*'Returns Stats'!C1402+B38*B38*'Returns Stats'!D1402+B38*B39*'Returns Stats'!E1402+B39*B36*'Returns Stats'!B1403+B39*B37*'Returns Stats'!C1403+B39*B38*'Returns Stats'!D1403+B39*B39*'Returns Stats'!E1403 -> 0.0064382899
A42: Portfolio Std Dev | B42: =SQRT(B41) -> 0.080238955
A45: Efficient Frontier (simulated points)
A46: Volatility (Std Dev) | B46: Expected Return
A47: 0.081645019 | B47: 0.040964785
A48: 0.080362304 | B48: 0.044616957
A49: 0.080341814 | B49: 0.04826913
A50: 0.081246549 | B50: 0.051921302
A51: 0.083531719 | B51: 0.055573474
...

Sheet Portfolio Returns
A3: Date | B3: Portfolio Daily Return
A4: ='Returns Stats'!A4 -> 2021-01-07 | B4: ='MPT Optimisation'!$B$16*'Returns Stats'!B4+'MPT Optimisation'!$B$17*'Returns Stats'!C4+'MPT Optimisation'!$B$18*'Returns Stats'!D4+'MPT Optimisation'!$B$19*'Returns Stats'!E4 -> 0.0097950506
A5: ='Returns Stats'!A5 -> 2021-01-08 | B5: ='MPT Optimisation'!$B$16*'Returns Stats'!B5+'MPT Optimisation'!$B$17*'Returns Stats'!C5+'MPT Optimisation'!$B$18*'Returns Stats'!D5+'MPT Optimisation'!$B$19*'Returns Stats'!E5 -> 0.0061301513
A6: ='Returns Stats'!A6 -> 2021-01-11 | B6: ='MPT Optimisation'!$B$16*'Returns Stats'!B6+'MPT Optimisation'!$B$17*'Returns Stats'!C6+'MPT Optimisation'!$B$18*'Returns Stats'!D6+'MPT Optimisation'!$B$19*'Returns Stats'!E6 -> -0.0082485834
A7: ='Returns Stats'!A7 -> 2021-01-12 | B7: ='MPT Optimisation'!$B$16*'Returns Stats'!B7+'MPT Optimisation'!$B$17*'Returns Stats'!C7+'MPT Optimisation'!$B$18*'Returns Stats'!D7+'MPT Optimisation'!$B$19*'Returns Stats'!E7 -> 0.0036440014
A8: ='Returns Stats'!A8 -> 2021-01-13 | B8: ='MPT Optimisation'!$B$16*'Returns Stats'!B8+'MPT Optimisation'!$B$17*'Returns Stats'!C8+'MPT Optimisation'!$B$18*'Returns Stats'!D8+'MPT Optimisation'!$B$19*'Returns Stats'!E8 -> 0.0010313875
A9: ='Returns Stats'!A9 -> 2021-01-14 | B9: ='MPT Optimisation'!$B$16*'Returns Stats'!B9+'MPT Optimisation'!$B$17*'Returns Stats'!C9+'MPT Optimisation'!$B$18*'Returns Stats'!D9+'MPT Optimisation'!$B$19*'Returns Stats'!E9 -> 0.0020242777
A10: ='Returns Stats'!A10 -> 2021-01-15 | B10: ='MPT Optimisation'!$B$16*'Returns Stats'!B10+'MPT Optimisation'!$B$17*'Returns Stats'!C10+'MPT Optimisation'!$B$18*'Returns Stats'!D10+'MPT Optimisation'!$B$19*'Returns Stats'!E10 -> -0.009280251
A11: ='Returns Stats'!A11 -> 2021-01-19 | B11: ='MPT Optimisation'!$B$16*'Returns Stats'!B11+'MPT Optimisation'!$B$17*'Returns Stats'!C11+'MPT Optimisation'!$B$18*'Returns Stats'!D11+'MPT Optimisation'!$B$19*'Returns Stats'!E11 -> 0.0075843972
A12: ='Returns Stats'!A12 -> 2021-01-20 | B12: ='MPT Optimisation'!$B$16*'Returns Stats'!B12+'MPT Optimisation'!$B$17*'Returns Stats'!C12+'MPT Optimisation'!$B$18*'Returns Stats'!D12+'MPT Optimisation'!$B$19*'Returns Stats'!E12 -> 0.010573095
A13: ='Returns Stats'!A13 -> 2021-01-21 | B13: ='MPT Optimisation'!$B$16*'Returns Stats'!B13+'MPT Optimisation'!$B$17*'Returns Stats'!C13+'MPT Optimisation'!$B$18*'Returns Stats'!D13+'MPT Optimisation'!$B$19*'Returns Stats'!E13 -> -0.00051933432
A14: ='Returns Stats'!A14 -> 2021-01-22 | B14: ='MPT Optimisation'!$B$16*'Returns Stats'!B14+'MPT Optimisation'!$B$17*'Returns Stats'!C14+'MPT Optimisation'!$B$18*'Returns Stats'!D14+'MPT Optimisation'!$B$19*'Returns Stats'!E14 -> -0.00229712
A15: ='Returns Stats'!A15 -> 2021-01-25 | B15: ='MPT Optimisation'!$B$16*'Returns Stats'!B15+'MPT Optimisation'!$B$17*'Returns Stats'!C15+'MPT Optimisation'!$B$18*'Returns Stats'!D15+'MPT Optimisation'!$B$19*'Returns Stats'!E15 -> 0.0018498825
... A1378: ='Returns Stats'!A1378 -> 2026-06-30 | B1378: ='MPT Optimisation'!$B$16*'Returns Stats'!B1378+'MPT Optimisation'!$B$17*'Returns Stats'!C1378+'MPT Optimisation'!$B$18*'Returns Stats'!D1378+'MPT Optimisation'!$B$19*'Returns Stats'!E1378 -> 0.0049468374

Sheet Normal VaR
A3: Portfolio Value (USD) | B3: ='MPT Optimisation'!B3 -> 20000000
A4: Portfolio Daily Mean Return | B4: =AVERAGE('Portfolio Returns'!B4:B1378) -> 0.00048908035
A5: Portfolio Daily Std Dev | B5: =STDEV('Portfolio Returns'!B4:B1378) -> 0.0096587344
A7: Confidence Level | B7: 95% | C7: z-score | D7: VaR (%) | E7: VaR (USD)
A8: 95% confidence | B8: 0.95 | C8: =NORMSINV(B8) -> 1.6448536 | D8: =C8*$B$5-$B$4 -> 0.015398124 | E8: =D8*$B$3 -> 307962.48
A9: 99% confidence | B9: 0.99 | C9: =NORMSINV(B9) -> 2.3263479 | D9: =C9*$B$5-$B$4 -> 0.021980496 | E9: =D9*$B$3 -> 439609.92

Sheet Historical VaR
A3: Portfolio Value (USD) | B3: ='MPT Optimisation'!B3 -> 20000000
A7: Confidence Level | B7: Percentile | C7: VaR (%) | D7: VaR (USD)
A8: 95% confidence | B8: 0.05 | C8: =-PERCENTILE('Portfolio Returns'!B4:B1378,B8) -> 0.014680101 | D8: =C8*$B$3 -> 293602.02
A9: 99% confidence | B9: 0.01 | C9: =-PERCENTILE('Portfolio Returns'!B4:B1378,B9) -> 0.026258658 | D9: =C9*$B$3 -> 525173.16

Sheet Monte Carlo VaR
H1: Simulated Portfolio Returns (raw draws)
H2: -0.0039106697
A3: Portfolio Value (USD) | B3: ='MPT Optimisation'!B3 -> 20000000 | H3: 0.002005887
A4: Simulations | B4: 10000 | H4: 0.0038814809
H5: 0.0040862335
H6: 0.0095718986
H7: -0.01319471
A8: Confidence Level | B8: Percentile | C8: VaR (%) | D8: VaR (USD) | H8: 0.0065037357
A9: 95% confidence | B9: 0.05 | C9: =-PERCENTILE(H2:H10001,B9) -> 0.015608655 | D9: =C9*$B$3 -> 312173.1 | H9: 0.0079488566
A10: 99% confidence | B10: 0.01 | C10: =-PERCENTILE(H2:H10001,B10) -> 0.02222009 | D10: =C10*$B$3 -> 444401.8 | H10: 0.001893375
H11: 0.0043892461
H12: -0.0067875972
H13: 0.016728505
H14: 0.00094488341
H15: 0.0047364667
H16: 0.0090515616
H17: 0.0060131848
H18: -0.0098285214
H19: -0.001204108
H20: -9.5221757e-05
H21: -0.00038316945
H22: 0.00016045868
... H10001: -0.0040497549

Sheet VaR Comparison
A3: Method | B3: VaR @ 95% (1-day) | C3: VaR @ 99% (1-day)
A4: Normal (Parametric) VaR | B4: ='Normal VaR'!E8 -> 307962.48 | C4: ='Normal VaR'!E9 -> 439609.92
A5: Historical Simulation VaR | B5: ='Historical VaR'!D8 -> 293602.02 | C5: ='Historical VaR'!D9 -> 525173.16
A6: Monte Carlo Simulation VaR | B6: ='Monte Carlo VaR'!D9 -> 312173.1 | C6: ='Monte Carlo VaR'!D10 -> 444401.8
A8: As % of Portfolio Value
A9: Method | B9: VaR @ 95% | C9: VaR @ 99%
A10: Normal (Parametric) VaR | B10: =B4/'MPT Optimisation'!B3 -> 0.015398124 | C10: =C4/'MPT Optimisation'!B3 -> 0.021980496
A11: Historical Simulation VaR | B11: =B5/'MPT Optimisation'!B3 -> 0.014680101 | C11: =C5/'MPT Optimisation'!B3 -> 0.026258658
A12: Monte Carlo Simulation VaR | B12: =B6/'MPT Optimisation'!B3 -> 0.015608655 | C12: =C6/'MPT Optimisation'!B3 -> 0.02222009

Sheet Bond Analysis
A3: Bond Inputs
A4: Issuer | B4: Microsoft Corporation
A5: ISIN | B5: US594918BC73
A6: Coupon Rate (annual) | B6: 0.035
A7: Payment Frequency (per year) | B7: 2
A8: Face Value (per $100 nominal) | B8: 100
A9: Yield to Maturity (market, current) | B9: 0.044
A10: Years to Maturity (approx. from mid-2026) | B10: 8.6
A12: N (number of coupon periods) | B12: =ROUND(B10*B7,0) -> 17
A13: Coupon payment per period | B13: =B8*B6/B7 -> 1.75
A14: Periodic yield (y) | B14: =B9/B7 -> 0.022
A16: Bond Price (via PV of Cash Flows)
A17: Bond Price | B17: =C43 -> 93.674883
A19: Duration and Convexity
A20: Macaulay Duration (years) | B20: =(D43/B7)/B17 -> 7.381243
A21: Modified Duration (years) | B21: =B20/(1+B14) -> 7.2223512
A22: Convexity | B22: =E43/(B17*B7^2*(1+B14)^2) -> 60.559106
A24: Cash Flow Schedule (used to derive Macaulay Duration and Convexity)
A25: Period (t) | B25: Cash Flow | C25: PV of Cash Flow | D25: PV × t | E25: PV × t × (t+1)
A26: 1 | B26: =B13 -> 1.75 | C26: =B26/(1+B14)^A26 -> 1.7123288 | D26: =C26*A26 -> 1.7123288 | E26: =C26*A26*(A26+1) -> 3.4246575
A27: 2 | B27: =B13 -> 1.75 | C27: =B27/(1+B14)^A27 -> 1.6754685 | D27: =C27*A27 -> 3.3509369 | E27: =C27*A27*(A27+1) -> 10.052811
A28: 3 | B28: =B13 -> 1.75 | C28: =B28/(1+B14)^A28 -> 1.6394016 | D28: =C28*A28 -> 4.9182049 | E28: =C28*A28*(A28+1) -> 19.67282
A29: 4 | B29: =B13 -> 1.75 | C29: =B29/(1+B14)^A29 -> 1.6041112 | D29: =C29*A29 -> 6.4164447 | E29: =C29*A29*(A29+1) -> 32.082224
A30: 5 | B30: =B13 -> 1.75 | C30: =B30/(1+B14)^A30 -> 1.5695804 | D30: =C30*A30 -> 7.8479021 | E30: =C30*A30*(A30+1) -> 47.087412
A31: 6 | B31: =B13 -> 1.75 | C31: =B31/(1+B14)^A31 -> 1.535793 | D31: =C31*A31 -> 9.2147578 | E31: =C31*A31*(A31+1) -> 64.503305
A32: 7 | B32: =B13 -> 1.75 | C32: =B32/(1+B14)^A32 -> 1.5027328 | D32: =C32*A32 -> 10.51913 | E32: =C32*A32*(A32+1) -> 84.153039
A33: 8 | B33: =B13 -> 1.75 | C33: =B33/(1+B14)^A33 -> 1.4703844 | D33: =C33*A33 -> 11.763075 | E33: =C33*A33*(A33+1) -> 105.86768
A34: 9 | B34: =B13 -> 1.75 | C34: =B34/(1+B14)^A34 -> 1.4387323 | D34: =C34*A34 -> 12.94859 | E34: =C34*A34*(A34+1) -> 129.4859
A35: 10 | B35: =B13 -> 1.75 | C35: =B35/(1+B14)^A35 -> 1.4077615 | D35: =C35*A35 -> 14.077615 | E35: =C35*A35*(A35+1) -> 154.85377
A36: 11 | B36: =B13 -> 1.75 | C36: =B36/(1+B14)^A36 -> 1.3774575 | D36: =C36*A36 -> 15.152032 | E36: =C36*A36*(A36+1) -> 181.82438
A37: 12 | B37: =B13 -> 1.75 | C37: =B37/(1+B14)^A37 -> 1.3478057 | D37: =C37*A37 -> 16.173669 | E37: =C37*A37*(A37+1) -> 210.25769
A38: 13 | B38: =B13 -> 1.75 | C38: =B38/(1+B14)^A38 -> 1.3187923 | D38: =C38*A38 -> 17.1443 | E38: =C38*A38*(A38+1) -> 240.0202
A39: 14 | B39: =B13 -> 1.75 | C39: =B39/(1+B14)^A39 -> 1.2904034 | D39: =C39*A39 -> 18.065648 | E39: =C39*A39*(A39+1) -> 270.98472
A40: 15 | B40: =B13 -> 1.75 | C40: =B40/(1+B14)^A40 -> 1.2626257 | D40: =C40*A40 -> 18.939385 | E40: =C40*A40*(A40+1) -> 303.03016
A41: 16 | B41: =B13 -> 1.75 | C41: =B41/(1+B14)^A41 -> 1.2354459 | D41: =C41*A41 -> 19.767134 | E41: =C41*A41*(A41+1) -> 336.04127
A42: 17 | B42: =B13+B8 -> 101.75 | C42: =B42/(1+B14)^A42 -> 70.286058 | D42: =C42*A42 -> 1194.863 | E42: =C42*A42*(A42+1) -> 21507.534
A43: Sum | C43: =SUM(C26:C42) -> 93.674883 | D43: =SUM(D26:D42) -> 1382.8741 | E43: =SUM(E26:E42) -> 23700.876
A45: Interest Rate Sensitivity — Unanticipated 25bp Fed Rate Cut
A46: Change in Yield (Δy) | B46: -0.0025
A47: % Price Change (Duration only) | B47: =-B21*B46 -> 0.018055878
...
